<?xml version="1.0" ?>
<sdf version="1.9" >

<model name='magni' >
  <link name="base_footprint" />
  <joint name="base_footprint_joint" type="fixed" >
    <parent>base_footprint</parent>
    <child>base_link</child>
  </joint>
  <link name="base_link" >
      <pose>0 0 0.07 0 0 0</pose>
      <inertial>
        <mass>10.0</mass>
        <pose>-0.15 0 0.03 0 0 0 </pose>
        <inertia>
          <ixx>0.059450809553</ixx>
          <ixy>0.0</ixy>
          <ixz>0.0</ixz>
          <iyy>0.150753273032</iyy>
          <iyz>0.0</iyz>
          <izz>0.17270409758500002</izz>
        </inertia>
      </inertial>

      <visual name='base_visual'>
          <geometry>
            <mesh>
              <uri>model://magni/meshes/magni_body.dae</uri>
            </mesh>
          </geometry>
      </visual>

      <collision name='base_collider_1'>
        <pose>0 0 0.05099999999999999 0 0 0</pose>
        <geometry>
          <box> <size>0.398 0.268 0.160</size></box>
        </geometry>
      </collision>
      
      <collision name='base_collider_2'>
        <pose>-0.026 0 0.148 0 0 0</pose>
        <geometry>
          <box> <size>0.375 0.268 0.034</size></box>
        </geometry>
      </collision>
      
      <collision name='base_collider_3'>
        <pose>-0.169 0.169 0.0059999999999999915 0 0 0</pose>
        <geometry>
          <box><size>0.1 0.07 0.07</size></box>
        </geometry>
      </collision>

      <collision name='base_collider_4'>
        <pose>-0.169 -0.169 0.0059999999999999915 0 0 0</pose>
        <geometry>
          <box><size>0.1 0.07 0.07</size></box>
        </geometry>
      </collision>
  </link>

  <!-- LEFT WHEEL -->

  <link name="left_wheel">
    <collision name="left_wheel_collider">
      <pose>0.063 0 0 0 1.5707963267948966 0</pose>
      <geometry>
        <cylinder>
         <length>0.01</length>
         <radius>0.1</radius>
        </cylinder>
      </geometry>
    </collision>

    <visual name="left_wheel_vis">
      <pose>-0.0 0 0 0 0 0</pose>
      <geometry>
        <mesh>
          <uri>model://magni/meshes/front_wheel.dae</uri>
        </mesh>
      </geometry>
    </visual>

    <inertial>
      <mass>1.34</mass>
      <pose>0 0 0 0 1.5707963267948966 0</pose>
      <inertia>
       <ixx>0.003629165215000001</ixx>
       <ixy>0.0</ixy>
       <ixz>0.0</ixz>
       <iyy>0.003629165215000001</iyy>
       <iyz>0.0</iyz>
       <izz>0.006700000000000001</izz>
      </inertia>
    </inertial>

    <pose>0.15 0.123 0.07 0 0 1.5707963267948966</pose>

  </link>

  <joint name="left_wheel_joint" type="revolute">
    <axis><xyz>1 0 0</xyz></axis>
    <parent>base_link</parent>
    <child>left_wheel</child>
  </joint>

  <!-- RIGHT WHEEL -->

  <link name="right_wheel">
    <collision name="right_wheel_collider">
      <pose>0.093 0 0 0 1.5707963267948966 0</pose>
      <geometry>
        <cylinder>
         <length>0.01</length>
         <radius>0.1</radius>
        </cylinder>
      </geometry>
    </collision>

    <visual name="right_wheel_vis">
      <pose>0.03 0 0 0 0 0</pose>
      <geometry>
        <mesh>
          <uri>model://magni/meshes/front_wheel.dae</uri>
        </mesh>
      </geometry>
    </visual>

    <inertial>
      <mass>1.34</mass>
      <pose>0 0 0 0 1.5707963267948966 0</pose>
      <inertia>
       <ixx>0.003629165215000001</ixx>
       <ixy>0.0</ixy>
       <ixz>0.0</ixz>
       <iyy>0.003629165215000001</iyy>
       <iyz>0.0</iyz>
       <izz>0.006700000000000001</izz>
      </inertia>
    </inertial>

    <pose>0.15 -0.0715 0.07 0 0 -1.5707963267948966</pose>

  </link>

  <joint name="right_wheel_joint" type="revolute">
    <axis><xyz>-1 0 0</xyz></axis>
    <parent>base_link</parent>
    <child>right_wheel</child>
  </joint>

  <!-- LEFT CASTER WHEEL -->

  <link name="left_caster_wheel">
    <collision name="left_caster_wheel_collider">
      <pose>0 0 -0.06 0 0 0</pose>
      <geometry>
        <sphere>
         <radius>0.04</radius>
        </sphere>
      </geometry>
      <surface>
        <friction>
          <ode>
            <mu>0.01</mu>
          </ode>
        </friction>
      </surface>
    </collision>

    <visual name="left_caster_wheel_vis">
      <geometry>
        <mesh>
          <uri>model://magni/meshes/caster_wheel.dae</uri>
        </mesh>
      </geometry>
    </visual>

    <pose>-0.17 0.168 0.06 0 0 3.141</pose>
  </link>

  <joint name="left_caster_wheel_joint" type="fixed">
    <parent>base_link</parent>
    <child>left_caster_wheel</child>
  </joint>


  <!-- RIGHT CASTER WHEEL -->

  <link name="right_caster_wheel">
    <collision name="right_caster_wheel_collider">
      <pose>0 0 -0.06 0 0 0</pose>
      <geometry>
        <sphere>
         <radius>0.04</radius>
        </sphere>
      </geometry>
      <surface>
          <friction>
            <ode>
              <mu>0.01</mu>
            </ode>
          </friction>
        </surface>
    </collision>

    <visual name="right_caster_wheel_vis">
      <geometry>
        <mesh>
          <uri>model://magni/meshes/caster_wheel.dae</uri>
        </mesh>
      </geometry>
    </visual>

    <pose>-0.17 -0.169 0.06 0 0 3.141</pose>
  </link>

  <joint name="right_caster_wheel_joint" type="fixed">
    <parent>base_link</parent>
    <child>right_caster_wheel</child>
  </joint>


</model>
</sdf>