<?xml version="1.0" ?>
<robot name="Haul Truck">
  <!--Generated by CROSS, a ROS Workbench for FreeCAD (https://github.com/galou/freecad.cross)-->
  <link name="chassis_link">
    <visual>
      <!--Chassis/Body.-->
      <origin xyz="0.0 0.0 0.0" rpy="0.0 -0.0 0.0"/>
      <geometry>
        <mesh filename="package://freecad_output/meshes/safeai_Body.dae"/>
      </geometry>
    </visual>
    <collision>
      <!--real_chassis_link_.Body_bbox-->
      <origin xyz="0.090073 5.25 3.35026" rpy="0.0 -0.0 0.0"/>
      <geometry>
        <box size="7.6383887394832115 10.500000000000005 4.84423459552541"/>
      </geometry>
    </collision>
    <inertial>
      <mass value="0.0"/>
      <origin xyz="0.0 0.0 0.0" rpy="0.0 -0.0 0.0"/>
      <inertia ixx="0.0" ixy="0.0" ixz="0.0" iyy="0.0" iyz="0.0" izz="0.0"/>
    </inertial>
  </link>
  <link name="tray_link">
    <visual>
      <!--Tray/Body002.-->
      <origin xyz="0.0 0.0 0.0" rpy="0.0 -0.0 0.0"/>
      <geometry>
        <mesh filename="package://freecad_output/meshes/safeai_Body002.dae"/>
      </geometry>
    </visual>
    <collision>
      <!--Tray/Body002.-->
      <origin xyz="0.0 0.0 0.0" rpy="0.0 -0.0 0.0"/>
      <geometry>
        <mesh filename="package://freecad_output/meshes/safeai_Body002.dae"/>
      </geometry>
    </collision>
    <inertial>
      <mass value="0.0"/>
      <origin xyz="0.0 0.0 0.0" rpy="0.0 -0.0 0.0"/>
      <inertia ixx="0.0" ixy="0.0" ixz="0.0" iyy="0.0" iyz="0.0" izz="0.0"/>
    </inertial>
  </link>
  <link name="front_left_wheel_link">
    <visual>
      <!--Wheel/Body001.-->
      <origin xyz="0.0 0.0 0.0" rpy="0.0 -0.0 0.0"/>
      <geometry>
        <mesh filename="package://freecad_output/meshes/safeai_Body001.dae"/>
      </geometry>
    </visual>
    <collision>
      <!--Wheel_collision/Pad012.-->
      <origin xyz="0.0 0.0 0.0" rpy="0.0 -0.0 0.0"/>
      <geometry>
        <mesh filename="package://freecad_output/meshes/safeai_Pad012.dae"/>
      </geometry>
    </collision>
    <inertial>
      <mass value="0.0"/>
      <origin xyz="0.0 0.0 0.0" rpy="0.0 -0.0 0.0"/>
      <inertia ixx="0.0" ixy="0.0" ixz="0.0" iyy="0.0" iyz="0.0" izz="0.0"/>
    </inertial>
  </link>
  <link name="front_right_wheel_link">
    <visual>
      <!--Wheel/Body001.-->
      <origin xyz="0.0 0.0 0.0" rpy="0.0 -0.0 0.0"/>
      <geometry>
        <mesh filename="package://freecad_output/meshes/safeai_Body001.dae"/>
      </geometry>
    </visual>
    <collision>
      <!--Wheel_collision/Pad012.-->
      <origin xyz="0.0 0.0 0.0" rpy="0.0 -0.0 0.0"/>
      <geometry>
        <mesh filename="package://freecad_output/meshes/safeai_Pad012.dae"/>
      </geometry>
    </collision>
    <inertial>
      <mass value="0.0"/>
      <origin xyz="0.0 0.0 0.0" rpy="0.0 -0.0 0.0"/>
      <inertia ixx="0.0" ixy="0.0" ixz="0.0" iyy="0.0" iyz="0.0" izz="0.0"/>
    </inertial>
  </link>
  <link name="rear_left_wheel_link">
    <visual>
      <!--Wheel/Body001.-->
      <origin xyz="0.0 0.0 0.0" rpy="0.0 -0.0 0.0"/>
      <geometry>
        <mesh filename="package://freecad_output/meshes/safeai_Body001.dae"/>
      </geometry>
    </visual>
    <collision>
      <!--Wheel_collision/Pad012.-->
      <origin xyz="0.0 0.0 0.0" rpy="0.0 -0.0 0.0"/>
      <geometry>
        <mesh filename="package://freecad_output/meshes/safeai_Pad012.dae"/>
      </geometry>
    </collision>
    <inertial>
      <mass value="0.0"/>
      <origin xyz="0.0 0.0 0.0" rpy="0.0 -0.0 0.0"/>
      <inertia ixx="0.0" ixy="0.0" ixz="0.0" iyy="0.0" iyz="0.0" izz="0.0"/>
    </inertial>
  </link>
  <link name="rear_right_wheel_link">
    <visual>
      <!--Wheel/Body001.-->
      <origin xyz="0.0 0.0 0.0" rpy="0.0 -0.0 0.0"/>
      <geometry>
        <mesh filename="package://freecad_output/meshes/safeai_Body001.dae"/>
      </geometry>
    </visual>
    <collision>
      <!--Wheel_collision/Pad012.-->
      <origin xyz="0.0 0.0 0.0" rpy="0.0 -0.0 0.0"/>
      <geometry>
        <mesh filename="package://freecad_output/meshes/safeai_Pad012.dae"/>
      </geometry>
    </collision>
    <inertial>
      <mass value="0.0"/>
      <origin xyz="0.0 0.0 0.0" rpy="0.0 -0.0 0.0"/>
      <inertia ixx="0.0" ixy="0.0" ixz="0.0" iyy="0.0" iyz="0.0" izz="0.0"/>
    </inertial>
  </link>
  <link name="lidar_link">
    <visual>
      <!--lidar_part/Mesh001.-->
      <origin xyz="0.0 0.0 0.0" rpy="0.0 -0.0 0.0"/>
      <geometry>
        <mesh filename="package://freecad_output/meshes/safeai_Mesh001.dae"/>
      </geometry>
    </visual>
    <visual>
      <!--lidar_part/Body007.-->
      <origin xyz="0.0 0.0 0.0" rpy="0.0 -0.0 0.0"/>
      <geometry>
        <mesh filename="package://freecad_output/meshes/safeai_Body007.dae"/>
      </geometry>
    </visual>
    <collision>
      <!--lidar_part/Mesh001.-->
      <origin xyz="0.0 0.0 0.0" rpy="0.0 -0.0 0.0"/>
      <geometry>
        <mesh filename="package://freecad_output/meshes/safeai_Mesh001.dae"/>
      </geometry>
    </collision>
    <collision>
      <!--lidar_part/Body007.-->
      <origin xyz="0.0 0.0 0.0" rpy="0.0 -0.0 0.0"/>
      <geometry>
        <mesh filename="package://freecad_output/meshes/safeai_Body007.dae"/>
      </geometry>
    </collision>
    <inertial>
      <mass value="0.0"/>
      <origin xyz="0.0 0.0 0.0" rpy="0.0 -0.0 0.0"/>
      <inertia ixx="0.0" ixy="0.0" ixz="0.0" iyy="0.0" iyz="0.0" izz="0.0"/>
    </inertial>
  </link>
  <joint name="tray_joint" type="fixed">
    <parent link="chassis_link"/>
    <child link="tray_link"/>
    <origin xyz="-3.8 13.0 3.1" rpy="0.0 -0.0 0.0"/>
  </joint>
  <joint name="front_left_wheel_joint" type="continuous">
    <parent link="chassis_link"/>
    <child link="front_left_wheel_link"/>
    <origin xyz="2.8 3.2 0.6" rpy="0.0 -0.0 0.0"/>
    <axis xyz="0 0 1"/>
    <limit lower="0.0" upper="0.0" velocity="0.0" effort="0.0"/>
  </joint>
  <joint name="front_right_wheel_joint" type="continuous">
    <parent link="chassis_link"/>
    <child link="front_right_wheel_link"/>
    <origin xyz="-4.0 3.2 0.6" rpy="0.0 -0.0 0.0"/>
    <axis xyz="0 0 1"/>
    <limit lower="0.0" upper="0.0" velocity="0.0" effort="0.0"/>
  </joint>
  <joint name="rear_left_wheel_joint" type="continuous">
    <parent link="chassis_link"/>
    <child link="rear_left_wheel_link"/>
    <origin xyz="2.8 9.3 0.6" rpy="0.0 -0.0 0.0"/>
    <axis xyz="0 0 1"/>
    <limit lower="0.0" upper="0.0" velocity="0.0" effort="0.0"/>
  </joint>
  <joint name="rear_right_wheel_joint" type="continuous">
    <parent link="chassis_link"/>
    <child link="rear_right_wheel_link"/>
    <origin xyz="-4.0 9.3 0.6" rpy="0.0 -0.0 0.0"/>
    <axis xyz="0 0 1"/>
    <limit lower="0.0" upper="0.0" velocity="0.0" effort="0.0"/>
  </joint>
  <joint name="lidar_joint" type="fixed">
    <parent link="chassis_link"/>
    <child link="lidar_link"/>
    <origin xyz="0.0 0.8 5.7" rpy="0.0 -0.0 0.0"/>
  </joint>
</robot>
