<?xml version="1.0" ?>
<robot name="Robot">
  <!--Generated by CROSS, a ROS Workbench for FreeCAD (https://github.com/galou/freecad.cross)-->
  <link name="chassis_link">
    <visual>
      <!--chassis/Body.-->
      <origin xyz="0.0 0.0 0.0" rpy="0.0 -0.0 0.0"/>
      <geometry>
        <mesh filename="package://freecad_scorpion/meshes/Unnamed_chassis_body.dae"/>
      </geometry>
    </visual>
    <inertial>
      <mass value="0.0"/>
      <origin xyz="0.0 0.0 0.0" rpy="0.0 -0.0 0.0"/>
      <inertia ixx="0.0" ixy="0.0" ixz="0.0" iyy="0.0" iyz="0.0" izz="0.0"/>
    </inertial>
  </link>
  <link name="tail_link1">
    <visual>
      <!--tail1/Body001.-->
      <origin xyz="0.0 0.0 0.0" rpy="0.0 -0.0 0.0"/>
      <geometry>
        <mesh filename="package://freecad_scorpion/meshes/Unnamed_tail1_body.dae"/>
      </geometry>
    </visual>
    <inertial>
      <mass value="0.0"/>
      <origin xyz="0.0 0.0 0.0" rpy="0.0 -0.0 0.0"/>
      <inertia ixx="0.0" ixy="0.0" ixz="0.0" iyy="0.0" iyz="0.0" izz="0.0"/>
    </inertial>
  </link>
  <link name="tail_link2">
    <visual>
      <!--tail2/Body002.-->
      <origin xyz="0.0 0.0 0.0" rpy="0.0 -0.0 0.0"/>
      <geometry>
        <mesh filename="package://freecad_scorpion/meshes/Unnamed_tail2_body.dae"/>
      </geometry>
    </visual>
    <inertial>
      <mass value="0.0"/>
      <origin xyz="0.0 0.0 0.0" rpy="0.0 -0.0 0.0"/>
      <inertia ixx="0.0" ixy="0.0" ixz="0.0" iyy="0.0" iyz="0.0" izz="0.0"/>
    </inertial>
  </link>
  <link name="tail_link3">
    <visual>
      <!--tail3/Body003.-->
      <origin xyz="0.0 0.0 0.0" rpy="0.0 -0.0 0.0"/>
      <geometry>
        <mesh filename="package://freecad_scorpion/meshes/Unnamed_tail3_body.dae"/>
      </geometry>
    </visual>
    <inertial>
      <mass value="0.0"/>
      <origin xyz="0.0 0.0 0.0" rpy="0.0 -0.0 0.0"/>
      <inertia ixx="0.0" ixy="0.0" ixz="0.0" iyy="0.0" iyz="0.0" izz="0.0"/>
    </inertial>
  </link>
  <link name="left_wheel_1">
    <visual>
      <!--wheel/Body004.-->
      <origin xyz="0.0 0.0 0.0" rpy="0.0 -0.0 0.0"/>
      <geometry>
        <mesh filename="package://freecad_scorpion/meshes/Unnamed_wheel_body.dae"/>
      </geometry>
    </visual>
    <inertial>
      <mass value="0.0"/>
      <origin xyz="0.0 0.0 0.0" rpy="0.0 -0.0 0.0"/>
      <inertia ixx="0.0" ixy="0.0" ixz="0.0" iyy="0.0" iyz="0.0" izz="0.0"/>
    </inertial>
  </link>
  <link name="right_wheel_1">
    <visual>
      <!--wheel/Body004.-->
      <origin xyz="0.0 0.0 0.0" rpy="0.0 -0.0 0.0"/>
      <geometry>
        <mesh filename="package://freecad_scorpion/meshes/Unnamed_wheel_body.dae"/>
      </geometry>
    </visual>
    <inertial>
      <mass value="0.0"/>
      <origin xyz="0.0 0.0 0.0" rpy="0.0 -0.0 0.0"/>
      <inertia ixx="0.0" ixy="0.0" ixz="0.0" iyy="0.0" iyz="0.0" izz="0.0"/>
    </inertial>
  </link>
  <link name="left_wheel_2">
    <visual>
      <!--wheel/Body004.-->
      <origin xyz="0.0 0.0 0.0" rpy="0.0 -0.0 0.0"/>
      <geometry>
        <mesh filename="package://freecad_scorpion/meshes/Unnamed_wheel_body.dae"/>
      </geometry>
    </visual>
    <inertial>
      <mass value="0.0"/>
      <origin xyz="0.0 0.0 0.0" rpy="0.0 -0.0 0.0"/>
      <inertia ixx="0.0" ixy="0.0" ixz="0.0" iyy="0.0" iyz="0.0" izz="0.0"/>
    </inertial>
  </link>
  <link name="right_wheel_2">
    <visual>
      <!--wheel/Body004.-->
      <origin xyz="0.0 0.0 0.0" rpy="0.0 -0.0 0.0"/>
      <geometry>
        <mesh filename="package://freecad_scorpion/meshes/Unnamed_wheel_body.dae"/>
      </geometry>
    </visual>
    <inertial>
      <mass value="0.0"/>
      <origin xyz="0.0 0.0 0.0" rpy="0.0 -0.0 0.0"/>
      <inertia ixx="0.0" ixy="0.0" ixz="0.0" iyy="0.0" iyz="0.0" izz="0.0"/>
    </inertial>
  </link>
  <link name="left_wheel_3">
    <visual>
      <!--wheel/Body004.-->
      <origin xyz="0.0 0.0 0.0" rpy="0.0 -0.0 0.0"/>
      <geometry>
        <mesh filename="package://freecad_scorpion/meshes/Unnamed_wheel_body.dae"/>
      </geometry>
    </visual>
    <inertial>
      <mass value="0.0"/>
      <origin xyz="0.0 0.0 0.0" rpy="0.0 -0.0 0.0"/>
      <inertia ixx="0.0" ixy="0.0" ixz="0.0" iyy="0.0" iyz="0.0" izz="0.0"/>
    </inertial>
  </link>
  <link name="right_wheel_3">
    <visual>
      <!--wheel/Body004.-->
      <origin xyz="0.0 0.0 0.0" rpy="0.0 -0.0 0.0"/>
      <geometry>
        <mesh filename="package://freecad_scorpion/meshes/Unnamed_wheel_body.dae"/>
      </geometry>
    </visual>
    <inertial>
      <mass value="0.0"/>
      <origin xyz="0.0 0.0 0.0" rpy="0.0 -0.0 0.0"/>
      <inertia ixx="0.0" ixy="0.0" ixz="0.0" iyy="0.0" iyz="0.0" izz="0.0"/>
    </inertial>
  </link>
  <joint name="joint_1" type="revolute">
    <parent link="chassis_link"/>
    <child link="tail_link1"/>
    <origin xyz="0.19 0.0 0.05" rpy="0.0 0.7853981633974484 0.0"/>
    <axis xyz="0 1 0"/>
    <limit lower="0.0" upper="3.141592653589793" velocity="0.0" effort="10.0"/>
  </joint>
  <joint name="joint_2" type="revolute">
    <parent link="tail_link1"/>
    <child link="tail_link2"/>
    <origin xyz="-0.065 0.0 -0.008" rpy="0.0 -0.0 0.0"/>
    <axis xyz="0 0 1"/>
    <limit lower="-1.5707963267948966" upper="1.5707963267948966" velocity="0.17453292519943295" effort="10.0"/>
  </joint>
  <joint name="joint_3" type="revolute">
    <parent link="tail_link2"/>
    <child link="tail_link3"/>
    <origin xyz="-0.046 0.0 0.0" rpy="0.0 -0.0 0.0"/>
    <axis xyz="0 1 0"/>
    <limit lower="-1.5707963267948966" upper="1.5707963267948966" velocity="0.017453292519943295" effort="10.0"/>
  </joint>
  <joint name="left_wheel_joint1" type="continuous">
    <parent link="chassis_link"/>
    <child link="left_wheel_1"/>
    <origin xyz="0.02 -0.033 0.015" rpy="0.0 -0.0 0.0"/>
    <axis xyz="0 1 0"/>
    <limit lower="0.0" upper="0.0" velocity="0.001" effort="10.0"/>
  </joint>
  <joint name="right_wheel_joint1" type="continuous">
    <parent link="chassis_link"/>
    <child link="right_wheel_1"/>
    <origin xyz="0.02 0.033 0.015" rpy="0.0 -0.0 0.0"/>
    <axis xyz="0 1 0"/>
    <limit lower="0.0" upper="0.0" velocity="0.001" effort="10.0"/>
  </joint>
  <joint name="left_wheel_joint2" type="continuous">
    <parent link="chassis_link"/>
    <child link="left_wheel_2"/>
    <origin xyz="0.09 -0.033 0.015" rpy="0.0 -0.0 0.0"/>
    <axis xyz="0 1 0"/>
    <limit lower="0.0" upper="0.0" velocity="0.001" effort="10.0"/>
  </joint>
  <joint name="right_wheel_joint2" type="continuous">
    <parent link="chassis_link"/>
    <child link="right_wheel_2"/>
    <origin xyz="0.09 0.033 0.015" rpy="0.0 -0.0 0.0"/>
    <axis xyz="0 1 0"/>
    <limit lower="0.0" upper="0.0" velocity="0.001" effort="10.0"/>
  </joint>
  <joint name="left_wheel_3_joint" type="continuous">
    <parent link="chassis_link"/>
    <child link="left_wheel_3"/>
    <origin xyz="0.16 -0.033 0.015" rpy="0.0 -0.0 0.0"/>
    <axis xyz="0 1 0"/>
    <limit lower="0.0" upper="0.0" velocity="0.001" effort="10.0"/>
  </joint>
  <joint name="right_wheel_3_joint" type="continuous">
    <parent link="chassis_link"/>
    <child link="right_wheel_3"/>
    <origin xyz="0.16 0.033 0.015" rpy="0.0 -0.0 0.0"/>
    <axis xyz="0 1 0"/>
    <limit lower="0.0" upper="0.0" velocity="0.001" effort="10.0"/>
  </joint>
</robot>
