<?xml version="1.0"?>
<robot xmlns:xacro="http://wiki.ros.org/xacro">
  <xacro:include filename="$(find veg_bot)/worlds_and_models/kuka/common_constants.xacro"/>
  <xacro:include filename="$(find veg_bot)/worlds_and_models/kuka/common_materials.xacro"/>
  <xacro:include filename="$(find start_creating_robots)/worlds_and_models/krytn/inertial.xacro" />

  <xacro:macro name="link_weight">
    <xacro:sphere_inertial radius="1" mass="2" />
  </xacro:macro>


  <xacro:macro name="kuka_kr6r900sixx" params="prefix">
    <link name="${prefix}base_link">
      <visual>
        <origin xyz="0 0 0" rpy="0 0 0"/>
        <geometry>
          <mesh filename="file://$(find veg_bot)/worlds_and_models/kuka/meshes/kr6_agilus/visual/base_link.dae" />
        </geometry>
        <xacro:material_kuka_pedestal />
      </visual>
      <collision>
        <origin xyz="-0.01 0 0" rpy="0 0 0"/>
        <geometry>
          <box size="0.33 0.21 0.4"/>
        </geometry>
      </collision>
      <xacro:link_weight />
    </link>
    <link name="${prefix}link_1">
      <visual>
        <origin xyz="0 0 0" rpy="0 0 0"/>
        <geometry>
          <mesh filename="file://$(find veg_bot)/worlds_and_models/kuka/meshes/kr6_agilus/visual/link_1.dae" />
        </geometry>
        <xacro:material_kuka_orange />
      </visual>
      <collision>
        <origin xyz="0 0 0" rpy="0 0 0"/>
        <geometry>
          <box size="0.24 0.28 0.27" />
        </geometry>
      </collision>
      <xacro:link_weight />
    </link>
    <link name="${prefix}link_2">
      <visual>
        <origin xyz="0 0 0" rpy="0 0 0"/>
        <geometry>
          <mesh filename="file://$(find veg_bot)/worlds_and_models/kuka/meshes/kr6r900sixx/visual/link_2.dae"/>
        </geometry>
        <xacro:material_kuka_orange />
      </visual>
      <collision>
        <origin xyz="0.1 0 0" rpy="0 0 0"/>
        <geometry>
          <box size="0.63 0.25 0.18" />
        </geometry>
      </collision>
      <xacro:link_weight />
    </link>
    <link name="${prefix}link_3">
      <visual>
        <origin xyz="0 0 0" rpy="0 0 0"/>
        <geometry>
          <mesh filename="file://$(find veg_bot)/worlds_and_models/kuka/meshes/kr6_agilus/visual/link_3.dae" />
        </geometry>
        <xacro:material_kuka_orange />
      </visual>
      <collision>
        <origin xyz="0.0 0 0" rpy="0 0 0"/>
        <geometry>
          <box size="0.19 0.13 0.17" />
        </geometry>
      </collision>
      <xacro:link_weight />
    </link>
    <link name="${prefix}link_4">
      <visual>
        <origin xyz="0 0 0" rpy="0 0 0"/>
        <geometry>
          <mesh filename="file://$(find veg_bot)/worlds_and_models/kuka/meshes/kr6r900sixx/visual/link_4.dae" />
        </geometry>
        <xacro:material_kuka_orange />
      </visual>
      <collision>
        <origin xyz="0.2 0 0" rpy="0 0 0"/>
        <geometry>
          <box size="0.45 0.12 0.13" />
        </geometry>
      </collision>
      <xacro:link_weight />
    </link>
    <link name="${prefix}link_5">
      <visual>
        <origin xyz="0 0 0" rpy="0 0 0"/>
        <geometry>
          <mesh filename="file://$(find veg_bot)/worlds_and_models/kuka/meshes/kr6_agilus/visual/link_5.dae" />
        </geometry>
        <xacro:material_kuka_orange />
      </visual>
      <collision>
        <origin xyz="0.01 0 0" rpy="0 0 0"/>
        <geometry>
          <box size="0.10 0.1 0.1" />
        </geometry>
      </collision>
      <xacro:link_weight />
    </link>
    <link name="${prefix}link_6">
      <visual>
        <origin xyz="0 0 0" rpy="0 0 0"/>
        <geometry>
          <mesh filename="file://$(find veg_bot)/worlds_and_models/kuka/meshes/kr6_agilus/visual/link_6.dae" />
        </geometry>
        <xacro:material_kuka_pedestal />
      </visual>
      <collision>
        <origin xyz="0 0 0" rpy="0 0 0"/>
        <geometry>
          <box size="0.013 0.040 0.04" />
        </geometry>
      </collision>
      <xacro:link_weight />
    </link>
    <!-- Following REP199, this frame shall be use to attach EEF or other equipment -->
    <link name="${prefix}flange" />

    <joint name="${prefix}joint_a1" type="revolute">
      <origin xyz="0 0 0.400" rpy="0 0 0"/>
      <parent link="${prefix}base_link"/>
      <child link="${prefix}link_1"/>
      <axis xyz="0 0 -1"/>
      <limit effort="0" lower="${-radians(170)}" upper="${radians(170)}" velocity="${radians(360)}"/>
    </joint>
    <joint name="${prefix}joint_a2" type="revolute">
      <origin xyz="0.025 0 0" rpy="0 0 0"/>
      <parent link="${prefix}link_1"/>
      <child link="${prefix}link_2"/>
      <axis xyz="0 1 0"/>
      <limit effort="0" lower="${-radians(190)}" upper="${radians(45)}" velocity="${radians(300)}"/>
    </joint>
    <joint name="${prefix}joint_a3" type="revolute">
      <origin xyz="0.455 0 0" rpy="0 0 0"/>
      <parent link="${prefix}link_2"/>
      <child link="${prefix}link_3"/>
      <axis xyz="0 1 0"/>
      <limit effort="0" lower="${-radians(120)}" upper="${radians(156)}" velocity="${radians(360)}"/>
    </joint>
    <joint name="${prefix}joint_a4" type="revolute">
      <origin xyz="0 0 0.035" rpy="0 0 0"/>
      <parent link="${prefix}link_3"/>
      <child link="${prefix}link_4"/>
      <axis xyz="-1 0 0"/>
      <limit effort="0" lower="${-radians(185)}" upper="${radians(185)}" velocity="${radians(381)}"/>
    </joint>
    <joint name="${prefix}joint_a5" type="revolute">
      <origin xyz="0.420 0 0" rpy="0 0 0"/>
      <parent link="${prefix}link_4"/>
      <child link="${prefix}link_5"/>
      <axis xyz="0 1 0"/>
      <limit effort="0" lower="${-radians(120)}" upper="${radians(120)}" velocity="${radians(388)}"/>
    </joint>
    <joint name="${prefix}joint_a6" type="revolute">
      <origin xyz="0.080 0 0" rpy="0 0 0"/>
      <parent link="${prefix}link_5"/>
      <child link="${prefix}link_6"/>
      <axis xyz="-1 0 0"/>
      <limit effort="0" lower="${-radians(350)}" upper="${radians(350)}" velocity="${radians(615)}"/>
    </joint>
    <joint name="${prefix}joint_a6-flange" type="fixed">
      <parent link="${prefix}link_6"/>
      <child link="${prefix}flange"/>
      <origin xyz="0 0 0" rpy="0 0 0"/>
    </joint>

    <!-- ROS base_link to KUKA $ROBROOT coordinate system transform -->
    <link name="${prefix}base" />
    <joint name="${prefix}base_link-base" type="fixed">
      <origin xyz="0 0 0" rpy="0 0 0"/>
      <parent link="${prefix}base_link"/>
      <child link="${prefix}base"/>
    </joint>

    <!-- This frame corresponds to the $TOOL coordinate system in KUKA KRC controllers -->
    <link name="${prefix}tool0">
      <visual>
        <origin xyz="0 0 0" rpy="0 0 0"/>
        <geometry>
          <mesh filename="file://$(find veg_bot)/worlds_and_models/kuka/meshes/end_effector.dae" />
        </geometry>
        <xacro:material_kuka_pedestal />
      </visual>
      <collision>
        <origin xyz="0 0 0" rpy="0 0 0"/>
        <geometry>
          <box size="0.32 0.1 0.1" />
        </geometry>
      </collision>
    </link>
    <joint name="${prefix}flange-tool0" type="fixed">
      <parent link="${prefix}flange"/>
      <child link="${prefix}tool0"/>
      <origin xyz="0 0 0" rpy="0 0 0"/>
    </joint>
  </xacro:macro>
</robot>
